<robot
  name="siaarm">
  <link
    name="base_link">
    <inertial>
      <origin
        xyz="-6.4185E-17 0.062924 0"
        rpy="0 3.1416 0" />
      <mass
        value="6.7406" />
      <inertia
        ixx="0.033492"
        ixy="-2.6365E-17"
        ixz="5.2001E-18"
        iyy="0.040462"
        iyz="2.2306E-17"
        izz="0.033492" />
    </inertial>
    <visual>
      <origin
        xyz="0 0 0"
        rpy="0 0 0" />
      <geometry>
        <mesh
          filename="meshes_siaarm/base_link.STL" />
      </geometry>
      <material
        name="">
        <color
          rgba="0.64706 0.61961 0.58824 1" />
      </material>
    </visual>
    <collision>
      <origin
        xyz="0 0 0"
        rpy="0 0 0" />
      <geometry>
        <mesh
          filename="meshes_siaarm/base_link.STL" />
      </geometry>
    </collision>
  </link>
  <link
    name="arm1">
    <inertial>
      <origin
        xyz="-0.020682 0.1229 4.5156E-05"
        rpy="0 0 0" />
      <mass
        value="0.33222" />
      <inertia
        ixx="0.0026785"
        ixy="0.00029038"
        ixz="-2.06E-07"
        iyy="0.0015913"
        iyz="-4.8054E-07"
        izz="0.0025051" />
    </inertial>
    <visual>
      <origin
        xyz="0 0 0"
        rpy="0 0 0" />
      <geometry>
        <mesh
          filename="meshes_siaarm/arm1.STL" />
      </geometry>
      <material
        name="">
        <color
          rgba="1 1 1 1" />
      </material>
    </visual>
    <collision>
      <origin
        xyz="0 0 0"
        rpy="0 0 0" />
      <geometry>
        <mesh
          filename="meshes_siaarm/arm1.STL" />
      </geometry>
    </collision>
  </link>
  <joint
    name="j1"
    type="revolute">
    <origin
      xyz="0 0.15 0"
      rpy="-3.1416 -0.62856 3.1416" />
    <parent
      link="base_link" />
    <child
      link="arm1" />
    <axis
      xyz="0 1 0" />
    <limit
      lower="-3.14"
      upper="3.14"
      effort="0"
      velocity="0" />
  </joint>
  <link
    name="arm2">
    <inertial>
      <origin
        xyz="0.0010896 0.058096 -0.32"
        rpy="0 0 0" />
      <mass
        value="0.91285" />
      <inertia
        ixx="0.054384"
        ixy="5.5878E-06"
        ixz="1.7872E-06"
        iyy="0.054708"
        iyz="-0.00014894"
        izz="0.0028672" />
    </inertial>
    <visual>
      <origin
        xyz="0 0 0"
        rpy="0 0 0" />
      <geometry>
        <mesh
          filename="meshes_siaarm/arm2.STL" />
      </geometry>
      <material
        name="">
        <color
          rgba="1 1 1 1" />
      </material>
    </visual>
    <collision>
      <origin
        xyz="0 0 0"
        rpy="0 0 0" />
      <geometry>
        <mesh
          filename="meshes_siaarm/arm2.STL" />
      </geometry>
    </collision>
  </link>
  <joint
    name="j2"
    type="revolute">
    <origin
      xyz="0.0295 0.1755 0"
      rpy="1.5708 1.5708 0" />
    <parent
      link="arm1" />
    <child
      link="arm2" />
    <axis
      xyz="0 1 0" />
    <limit
      lower="-1.57"
      upper="1.57"
      effort="0"
      velocity="0" />
  </joint>
  <link
    name="arm3">
    <inertial>
      <origin
        xyz="0.0013837 0.052028 -0.048543"
        rpy="0 0 0" />
      <mass
        value="0.33646" />
      <inertia
        ixx="0.0026"
        ixy="1.4343E-05"
        ixz="-3.2114E-05"
        iyy="0.0026807"
        iyz="-0.00032384"
        izz="0.001479" />
    </inertial>
    <visual>
      <origin
        xyz="0 0 0"
        rpy="0 0 0" />
      <geometry>
        <mesh
          filename="meshes_siaarm/arm3.STL" />
      </geometry>
      <material
        name="">
        <color
          rgba="1 1 1 1" />
      </material>
    </visual>
    <collision>
      <origin
        xyz="0 0 0"
        rpy="0 0 0" />
      <geometry>
        <mesh
          filename="meshes_siaarm/arm3.STL" />
      </geometry>
    </collision>
  </link>
  <joint
    name="j3"
    type="revolute">
    <origin
      xyz="0 0 -0.64"
      rpy="6.7856E-17 7.7112E-17 -3.1416" />
    <parent
      link="arm2" />
    <child
      link="arm3" />
    <axis
      xyz="0 1 0" />
    <limit
      lower="-2.5"
      upper="2.5"
      effort="0"
      velocity="0" />
  </joint>
  <link
    name="arm4">
    <inertial>
      <origin
        xyz="1.0739E-05 0.11285 0.030029"
        rpy="0 0 0" />
      <mass
        value="0.29612" />
      <inertia
        ixx="0.0020154"
        ixy="3.7006E-07"
        ixz="3.3626E-07"
        iyy="0.0012812"
        iyz="-0.00044113"
        izz="0.0020268" />
    </inertial>
    <visual>
      <origin
        xyz="0 0 0"
        rpy="0 0 0" />
      <geometry>
        <mesh
          filename="meshes_siaarm/arm4.STL" />
      </geometry>
      <material
        name="">
        <color
          rgba="1 1 1 1" />
      </material>
    </visual>
    <collision>
      <origin
        xyz="0 0 0"
        rpy="0 0 0" />
      <geometry>
        <mesh
          filename="meshes_siaarm/arm4.STL" />
      </geometry>
    </collision>
  </link>
  <joint
    name="j4"
    type="revolute">
    <origin
      xyz="0 0.0295 -0.1765"
      rpy="-1.5708 -2.213E-16 7.1054E-15" />
    <parent
      link="arm3" />
    <child
      link="arm4" />
    <axis
      xyz="0 1 0" />
    <limit
      lower="-3.14"
      upper="3.14"
      effort="0"
      velocity="0" />
  </joint>
  <link
    name="arm5">
    <inertial>
      <origin
        xyz="-2.3593E-05 0.029535 -0.059153"
        rpy="0 0 0" />
      <mass
        value="0.29615" />
      <inertia
        ixx="0.0020155"
        ixy="-3.5874E-07"
        ixz="-3.1879E-07"
        iyy="0.0020268"
        iyz="-0.00044115"
        izz="0.0012813" />
    </inertial>
    <visual>
      <origin
        xyz="0 0 0"
        rpy="0 0 0" />
      <geometry>
        <mesh
          filename="meshes_siaarm/arm5.STL" />
      </geometry>
      <material
        name="">
        <color
          rgba="1 1 1 1" />
      </material>
    </visual>
    <collision>
      <origin
        xyz="0 0 0"
        rpy="0 0 0" />
      <geometry>
        <mesh
          filename="meshes_siaarm/arm5.STL" />
      </geometry>
    </collision>
  </link>
  <joint
    name="j5"
    type="revolute">
    <origin
      xyz="0 0.172 0.0005"
      rpy="-1.5708 -5.5511E-16 3.1416" />
    <parent
      link="arm4" />
    <child
      link="arm5" />
    <axis
      xyz="0 1 0" />
    <limit
      lower="-1.57"
      upper="1.57"
      effort="0"
      velocity="0" />
  </joint>
  <link
    name="arm6">
    <inertial>
      <origin
        xyz="-1.3878E-17 0.06986 2.7756E-17"
        rpy="0 0 0" />
      <mass
        value="0.25088" />
      <inertia
        ixx="0.00054874"
        ixy="6.0589E-20"
        ixz="-9.4868E-20"
        iyy="0.00051459"
        iyz="4.4477E-20"
        izz="0.00054874" />
    </inertial>
    <visual>
      <origin
        xyz="0 0 0"
        rpy="0 0 0" />
      <geometry>
        <mesh
          filename="meshes_siaarm/arm6.STL" />
      </geometry>
      <material
        name="">
        <color
          rgba="1 1 1 1" />
      </material>
    </visual>
    <collision>
      <origin
        xyz="0 0 0"
        rpy="0 0 0" />
      <geometry>
        <mesh
          filename="meshes_siaarm/arm6.STL" />
      </geometry>
    </collision>
  </link>
  <joint
    name="j6"
    type="revolute">
    <origin
      xyz="0 -0.0005 -0.174"
      rpy="-1.5708 1.3531E-16 -0.40523" />
    <parent
      link="arm5" />
    <child
      link="arm6" />
    <axis
      xyz="0 1 0" />
    <limit
      lower="-3.14"
      upper="3.14"
      effort="0"
      velocity="0" />
  </joint>
</robot>
